Workbook

Sheet Leer primero
A1: MesaRPG — Modelo economico
A2: MRPG-FIN-01 Rev. A · 23-08-2026 · acompana a MRPG-BIZ-01 y MRPG-TABLE-02
A5: COMO USAR ESTE LIBRO
A7: 1. | B7: Cambia solo las celdas AZULES con fondo AMARILLO de la hoja 'Supuestos'. Todo lo demas se recalcula.
A8: 2. | B8: Las hojas 'BOM mesa' y 'BOM kit' tienen precios unitarios editables (azul) por si consigues otra oferta.
A9: 3. | B9: 'Economia unitaria' te dice lo que ganas por unidad. 'Escenarios' agrega la campana. 'Caja' proyecta 10 trimestres.
A10: 4. | B10: Ningun numero de este libro es un presupuesto cerrado. Son estimaciones de agosto de 2026 a verificar con proveedores.
A12: CODIGO DE COLOR
A14: Azul sobre amarillo | B14: Supuesto que debes revisar y cambiar. Es una decision tuya, no un dato.
A15: Azul | B15: Dato introducido a mano (precio de proveedor, tarifa, referencia de mercado).
A16: Negro | B16: Formula calculada dentro de la misma hoja. No tocar.
A17: Verde | B17: Formula que trae un valor de otra hoja. No tocar.
A19: DE DONDE SALEN LAS REFERENCIAS EXTERNAS
A21: Comisiones Kickstarter | B21: 5 % de plataforma + 3 % + 0,30 € de procesamiento para creadores en Espana (kickstarter.com/help/fees, ago-2026).
A22: Coste por email / seguidor | B22: 1-3 € por email, 2-5 € por seguidor de campana; conversion media seguidor->mecenas ~30 % (prelaunch.marketing, 2026).
A23: Transporte paletizado UE | B23: 36-84 € por palet desde Espana segun destino, tarifas B2B Q2-2026 (trans-road.com).
A24: Coste de marcado CE | B24: 750-1.500 € para electronica de red; 1.500-3.000 € si entra ensayo de radio (ecocomply.ai, 2026).
A25: Precios de componentes | B25: Raspberry Pi 5 y AI HAT+ de precio oficial; resto estimado a partir de catalogos de distribuidor, ago-2026.
A26: Precio de la competencia | B26: Arena de Game Theory Tables, mesa digital tactil 4K: 7.299 $ (gametheorytables.com, ago-2026).

Sheet Supuestos
A1: Supuestos
A2: Cambia solo las celdas azules sobre amarillo. Todas las demas hojas leen de aqui.
A4: GENERAL
A5: Tipo de IVA | B5: 0.21 | C5: Espana, tipo general.
A6: Horas dedicadas por semana | B6: 12 | C6: El recurso mas escaso del proyecto. Si baja de 8, el calendario se estira.
A7: Capital propio disponible | B7: 5000 | C7: Punto de partida declarado.
A9: SOFTWARE — FASE 1
A10: PVP licencia perpetua (sin IVA) | B10: 49 | C10: Referencia: Foundry VTT cobra 50 $ una sola vez.
A11: Comision de tienda y pago | B11: 0.12 | C11: itch.io + pasarela. Con venta directa propia baja al 4-6 %.
A12: Licencias vendidas — ano 1 | B12: 300 | C12: Umbral de la Puerta P1 del plan comercial.
A13: Licencias vendidas — ano 2 | B13: 1200
A14: Licencias vendidas — ano 3 | B14: 3000
A15: Suscriptores IA en nube (media ano 3) | B15: 250 | C15: Capa opcional de pago.
A16: Precio suscripcion mensual | B16: 5
A17: Coste de nube por suscriptor y mes | B17: 1.6 | C17: Inferencia LLM en nube. Verificar con proveedor real.
A19: KIT NUCLEO — FASE 2
A20: PVP kit (con IVA) | B20: 799 | C20: Pi 5 + AI HAT + camaras + LEDs + licencia, montado y calibrado.
A21: Unidades ano 2 | B21: 50 | C21: Umbral de la Puerta P2.
A22: Unidades ano 3 | B22: 250
A23: Coste de envio del kit (paquete 2,5 kg) | B23: 14 | C23: Paqueteria estandar UE. Se repercute al cliente.
A24: Tasa de devolucion del kit | B24: 0.06 | C24: Umbral de alarma de la Puerta P2: 8 %.
A25: Comision de pago del kit (tienda propia) | B25: 0.035 | C25: Pasarela de pago propia. Mucho mas baja que la comision de tienda de software.
A26: MESA — FASE 3
A27: PVP mesa Estandar (con IVA) | B27: 2899 | C27: La Arena de Game Theory Tables cuesta 7.299 $. Hay hueco por debajo.
A28: Sobreprecio SKU Premium (marco tactil IR) | B28: 400 | C28: Coste incremental ~130 € a 100 ud.
A29: % de pedidos Premium | B29: 0.3
A30: Comision de plataforma de campana | B30: 0.09 | C30: 5 % Kickstarter + ~3-4 % de procesamiento.
A31: Comision de gestor de pledges | B31: 0.04 | C31: Pledge manager y gestion de IVA.
A32: Marketing como % del ingreso neto | B32: 0.15 | C32: Referencia del sector: 15-25 % del objetivo de recaudacion.
A33: Envio cobrado al cliente | B33: 120
A34: Coste real de envio | B34: 130 | C34: 4 bultos de menos de 25 kg, o palet. Ver MRPG-TABLE-02 §11.
A35: Mesas vendidas en campana | B35: 150
A36: Mesas B2B previas a la campana | B36: 12 | C36: Umbral de la Puerta P3: minimo 10 instaladas.
A38: COSTES FIJOS Y DE ENTRADA
A39: Prototipos (3 iteraciones) | B39: 6000 | C39: Ver MRPG-BIZ-01 §01.
A40: Marcado CE (EMC + LVD + RED) | B40: 3500 | C40: 750-3.000 € segun si entra ensayo de radio.
A41: Expediente GPSR y analisis de riesgos | B41: 1200 | C41: Obligatorio desde el 13-12-2024.
A42: Utillaje y plantillas | B42: 9000 | C42: Matriz de plegado, plantillas CNC, cunas de embalaje.
A43: Cumplimiento anual (RAEE, envases, asesoria) | B43: 3500 | C43: Recurrente desde la Fase 3.
A44: Gastos fijos mensuales (cuota, software, hosting) | B44: 450 | C44: Autonomo o SL. Ajustar a tu situacion real.
...

Sheet BOM mesa
A1: Lista de materiales — mesa completa
A2: Precios estimados puesto en almacen, agosto 2026. Columnas azules editables.
A4: Partida | B4: Coste 1 ud. | C4: Coste 100 ud. | D4: Masa (kg) | E4: Nota
A5: Panel 55" 4K open frame | B5: 380 | C5: 290 | D5: 15 | E5: Verificar contorno exacto: varia ±8 mm entre fabricantes
A6: Vidrio 6 mm bajo hierro, AR, templado, cantos pulidos | B6: 130 | C6: 68 | D6: 13.2 | E6: 1240 x 712 mm. A 4 mm la flecha toca el panel
A7: Bastidor de acero cortado y plegado + pintura en polvo | B7: 220 | C7: 110 | D7: 16.1 | E7: Tubo 25x25x1,5 S235JR, ~14,5 m
A8: Faldon DM/chapado CNC + acabado | B8: 115 | C8: 58 | D8: 9.5 | E8: 18 mm, 4,9 m x 150 mm
A9: Bandeja inferior contrachapado 12 mm | B9: 0 | C9: 0 | D9: 6.7 | E9: Incluida en la partida de faldon
A10: Raspberry Pi 5 8 GB | B10: 82 | C10: 74 | D10: 0.1 | E10: Precio oficial
A11: AI HAT+ 26 TOPS (Hailo-8) | B11: 115 | C11: 100 | D11: 0.1 | E11: Precio oficial Raspberry Pi
A12: SSD NVMe 128 GB + adaptador | B12: 32 | C12: 24 | D12: 0.1
A13: Camaras CM3 Wide + CM3 NoIR + cables | B13: 72 | C13: 56 | D13: 0.2 | E13: Dos camaras: resuelve paralaje y oclusion por manos
A14: Iluminacion IR 850 nm + filtro paso banda | B14: 26 | C14: 15 | D14: 0.2 | E14: Hipotesis clave de MRPG-TABLE-02 §05
A15: Tira WS2815 4,1 m + ESP32 + canal y difusor | B15: 58 | C15: 36 | D15: 1.4 | E15: 12 V con linea de datos redundante
A16: Fuente 12 V 150 W + IEC/fusible/interruptor + mazo | B16: 58 | C16: 36 | D16: 1.5 | E16: Fuente con marcado CE propio
A17: Ventiladores 2 x 120 mm PWM + rejillas + filtro | B17: 20 | C17: 11 | D17: 0.5 | E17: 60 m3/h a 600-800 rpm
A18: Altavoces x2 + amplificador clase D | B18: 36 | C18: 22 | D18: 1.1
A19: Tornilleria, insertos M8, junta EPDM, pies regulables | B19: 38 | C19: 21 | D19: 1.6
A20: Embalaje: cajas, cuna de vidrio, espuma, impresion | B20: 58 | C20: 40 | D20: 1.7 | E20: 4 bultos de menos de 25 kg
A21: Subtotal materiales | B21: =SUM(B5:B20) -> 1440 | C21: =SUM(C5:C20) -> 961 | D21: =SUM(D5:D20) -> 69
A22: Montaje y control de calidad (1,5 h) | B22: 38 | C22: 38
A23: Reserva de merma y garantia | B23: 0.06
A24: COSTE UNITARIO PUESTO EN ALMACEN | B24: =ROUND(B21*(1+$B$23)+B22,0) -> 1564 | C24: =ROUND(C21*(1+$B$23)+C22,0) -> 1057
A25: Marco tactil IR 55" — solo SKU Premium | B25: 190 | C25: 130
A27: Masa total ensamblada (kg) | D27: =D21 -> 69
A28: Limite de paqueteria UE por bulto (kg) | D28: 31.5 | E28: Los transportistas UE cortan entre 20 y 31,5 kg segun servicio. 31,5 es el techo, no la norma: baja a 20 si quieres tarifa economica
A29: Bultos minimos necesarios | D29: =ROUNDUP((D21+7)/D28,0) -> 3 | E29: Se anaden 7 kg de embalaje al peso neto

Sheet BOM kit
A1: Lista de materiales — Kit Nucleo
A2: El cerebro sin el mueble: 2,5 kg, paqueteria estandar, sin red electrica interna.
A4: Partida | B4: Coste 1 ud. | C4: Coste 100 ud. | D4: Nota
A5: Raspberry Pi 5 8 GB | B5: 82 | C5: 74
A6: AI HAT+ 26 TOPS (Hailo-8) | B6: 115 | C6: 100
A7: SSD NVMe 128 GB + adaptador | B7: 32 | C7: 24
A8: Camaras CM3 Wide + CM3 NoIR + cables | B8: 72 | C8: 56 | D8: Dos camaras, ver MRPG-TABLE-02 §04
A9: Brazo/soporte de camara plegable | B9: 45 | C9: 26 | D9: Aluminio, mordaza universal para borde de mesa
A10: Iluminacion IR 850 nm + filtro | B10: 26 | C10: 15
A11: Tira WS2815 3 m + ESP32 + canal | B11: 48 | C11: 30
A12: Caja de aluminio + disipacion + ventilador | B12: 38 | C12: 22
A13: Fuente USB-C 27 W certificada | B13: 18 | C13: 12 | D13: Externa: evita meter red electrica en tu carcasa
A14: Embalaje + guia impresa + patron de calibracion | B14: 16 | C14: 10
A15: COSTE UNITARIO DEL KIT | B15: =SUM(B5:B14) -> 492 | C15: =SUM(C5:C14) -> 369

Sheet Economia unitaria
A1: Economia unitaria
A2: Que queda de cada unidad vendida, por linea de producto.
A4: Concepto | B4: Mesa Estandar | C4: Mesa Premium | D4: Kit Nucleo | E4: Nota
A5: PVP con IVA | B5: =Supuestos!$B$27 -> 2899 | C5: =Supuestos!$B$27+Supuestos!$B$28 -> 3299 | D5: =Supuestos!$B$20 -> 799
A6: IVA repercutido | B6: =-B5*Supuestos!$B$5/(1+Supuestos!$B$5) -> -503.13223 | C6: =-C5*Supuestos!$B$5/(1+Supuestos!$B$5) -> -572.55372 | D6: =-D5*Supuestos!$B$5/(1+Supuestos!$B$5) -> -138.66942
A7: Ingreso neto | B7: =B5+B6 -> 2395.8678 | C7: =C5+C6 -> 2726.4463 | D7: =D5+D6 -> 660.33058
A8: Coste de fabricacion (100 ud.) | B8: =-'BOM mesa'!$C$24 -> -1057 | C8: =-('BOM mesa'!$C$24+'BOM mesa'!$C$25) -> -1187 | D8: =-'BOM kit'!$C$15 -> -369
A9: Comision de plataforma o pasarela | B9: =-B5*Supuestos!$B$30 -> -260.91 | C9: =-C5*Supuestos!$B$30 -> -296.91 | D9: =-D5*Supuestos!$B$25 -> -27.965 | E9: La mesa se vende en campana con comision alta; el kit, en tienda propia con pasarela
A10: Comision de gestor de pledges | B10: =-B5*Supuestos!$B$31 -> -115.96 | C10: =-C5*Supuestos!$B$31 -> -131.96 | D10: 0
A11: Marketing amortizado | B11: =-B7*Supuestos!$B$32 -> -359.38017 | C11: =-C7*Supuestos!$B$32 -> -408.96694 | D11: =-D7*Supuestos!$B$32*0.5 -> -49.524793 | E11: El kit se vende con marketing ya pagado por la Fase 1
A12: Diferencia de envio (cobrado - real) | B12: =Supuestos!$B$33-Supuestos!$B$34 -> -10 | C12: =Supuestos!$B$33-Supuestos!$B$34 -> -10 | D12: 0
A13: Coste de devoluciones | B13: 0 | C13: 0 | D13: =-Supuestos!$B$24*D8*-1 -> -22.14 | E13: Kit: tasa de devolucion aplicada sobre el coste
A14: CONTRIBUCION POR UNIDAD | B14: =SUM(B7:B13) -> 592.6176 | C14: =SUM(C7:C13) -> 691.60934 | D14: =SUM(D7:D13) -> 191.70079
A15: Margen de contribucion sobre neto | B15: =IFERROR(B14/B7,0) -> 0.24734988 | C15: =IFERROR(C14/C7,0) -> 0.25366696 | D15: =IFERROR(D14/D7,0) -> 0.29031033
A17: SOFTWARE — licencia perpetua
A18: Concepto | B18: Por licencia | E18: Nota
A19: PVP sin IVA | B19: =Supuestos!$B$10 -> 49
A20: Comision de tienda y pago | B20: =-B19*Supuestos!$B$11 -> -5.88
A21: Coste marginal de servir | B21: 0 | E21: Descarga. Cero coste variable real
A22: CONTRIBUCION POR LICENCIA | B22: =SUM(B19:B21) -> 43.12
A23: Margen de contribucion | B23: =IFERROR(B22/B19,0) -> 0.88
A26: COMPARACION: cuanto hay que vender para ganar 100.000 € de contribucion
A27: Linea | B27: Unidades necesarias | C27: Recaudacion bruta
A28: Mesas Estandar | B28: =IFERROR(ROUNDUP(100000/B14,0),0) -> 169 | C28: =B28*B5 -> 489931
A29: Kits Nucleo | B29: =IFERROR(ROUNDUP(100000/D14,0),0) -> 522 | C29: =B29*D5 -> 417078
A30: Licencias de software | B30: =IFERROR(ROUNDUP(100000/B22,0),0) -> 2320 | C30: =B30*B19 -> 113680
A32: Esta tabla es el argumento numerico de toda la escalera del plan comercial: la misma contribucion con muchisimo menos riesgo fisico.

Sheet Escenarios
A1: Escenarios de campana
A2: Tres niveles de resultado. El escenario 'Base' usa los supuestos tal como estan.
A4: Concepto | B4: Pesimista | C4: Base | D4: Optimista | E4: Nota
A5: Mesas vendidas | B5: 60 | C5: =Supuestos!$B$35 -> 150 | D5: 320 | E5: Referencia: la campana de Arena, mesa digital de TTRPG, logro 266 mecenas en 2024
A6: % Premium | B6: =Supuestos!$B$29 -> 0.3 | C6: =Supuestos!$B$29 -> 0.3 | D6: =Supuestos!$B$29 -> 0.3
A7: Kits vendidos en la campana | B7: 40 | C7: 120 | D7: 400
A8: Licencias vendidas en la campana | B8: 150 | C8: 500 | D8: 1500
A10: RECAUDACION
A11: Mesas Estandar | B11: =B5*(1-B6)*'Economia unitaria'!$B$5 -> 121758 | C11: =C5*(1-C6)*'Economia unitaria'!$B$5 -> 304395 | D11: =D5*(1-D6)*'Economia unitaria'!$B$5 -> 649376
A12: Mesas Premium | B12: =B5*B6*'Economia unitaria'!$C$5 -> 59382 | C12: =C5*C6*'Economia unitaria'!$C$5 -> 148455 | D12: =D5*D6*'Economia unitaria'!$C$5 -> 316704
A13: Kits | B13: =B7*'Economia unitaria'!$D$5 -> 31960 | C13: =C7*'Economia unitaria'!$D$5 -> 95880 | D13: =D7*'Economia unitaria'!$D$5 -> 319600
A14: Licencias | B14: =B8*'Economia unitaria'!$B$19 -> 7350 | C14: =C8*'Economia unitaria'!$B$19 -> 24500 | D14: =D8*'Economia unitaria'!$B$19 -> 73500
A15: RECAUDACION BRUTA | B15: =SUM(B11:B14) -> 220450 | C15: =SUM(C11:C14) -> 573230 | D15: =SUM(D11:D14) -> 1359180
A17: CONTRIBUCION
A18: Mesas Estandar | B18: =B5*(1-B6)*'Economia unitaria'!$B$14 -> 24889.939 | C18: =C5*(1-C6)*'Economia unitaria'!$B$14 -> 62224.848 | D18: =D5*(1-D6)*'Economia unitaria'!$B$14 -> 132746.34
A19: Mesas Premium | B19: =B5*B6*'Economia unitaria'!$C$14 -> 12448.968 | C19: =C5*C6*'Economia unitaria'!$C$14 -> 31122.42 | D19: =D5*D6*'Economia unitaria'!$C$14 -> 66394.497
A20: Kits | B20: =B7*'Economia unitaria'!$D$14 -> 7668.0314 | C20: =C7*'Economia unitaria'!$D$14 -> 23004.094 | D20: =D7*'Economia unitaria'!$D$14 -> 76680.314
A21: Licencias | B21: =B8*'Economia unitaria'!$B$22 -> 6468 | C21: =C8*'Economia unitaria'!$B$22 -> 21560 | D21: =D8*'Economia unitaria'!$B$22 -> 64680
A22: CONTRIBUCION TOTAL | B22: =SUM(B18:B21) -> 51474.939 | C22: =SUM(C18:C21) -> 137911.36 | D22: =SUM(D18:D21) -> 340501.15
A24: COSTES DE ENTRADA A DESCONTAR (una sola vez)
A25: Prototipos | B25: =-Supuestos!$B$39 -> -6000 | C25: =-Supuestos!$B$39 -> -6000 | D25: =-Supuestos!$B$39 -> -6000
A26: Marcado CE | B26: =-Supuestos!$B$40 -> -3500 | C26: =-Supuestos!$B$40 -> -3500 | D26: =-Supuestos!$B$40 -> -3500
A27: Expediente GPSR | B27: =-Supuestos!$B$41 -> -1200 | C27: =-Supuestos!$B$41 -> -1200 | D27: =-Supuestos!$B$41 -> -1200
A28: Utillaje y plantillas | B28: =-Supuestos!$B$42 -> -9000 | C28: =-Supuestos!$B$42 -> -9000 | D28: =-Supuestos!$B$42 -> -9000
A29: RESULTADO DESPUES DE COSTES DE ENTRADA | B29: =B22+SUM(B25:B28) -> 31774.939 | C29: =C22+SUM(C25:C28) -> 118211.36 | D29: =D22+SUM(D25:D28) -> 320801.15
A31: PUNTO DE EQUILIBRIO
A32: Mesas necesarias para cubrir costes de entrada | B32: =IFERROR(ROUNDUP(-SUM(B25:B28)/'Economia unitaria'!$B$14,0),0) -> 34 | C32: =IFERROR(ROUNDUP(-SUM(C25:C28)/'Economia unitaria'!$B$14,0),0) -> 34 | D32: =IFERROR(ROUNDUP(-SUM(D25:D28)/'Economia unitaria'!$B$14,0),0) -> 34 | E32: Solo con mesas, sin contar kits ni licencias
A34: Aviso: la recaudacion bruta NO es dinero disponible. El IVA se liquida antes de fabricar; reservalo en cuenta separada el dia que entra.

Sheet Caja
A1: Proyeccion de caja — 10 trimestres
A2: Sigue la escalera del plan comercial. Trimestre 1 = mes 1-3.
A4: Concepto | B4: T1 | C4: T2 | D4: T3 | E4: T4 | F4: T5 | G4: T6 | H4: T7 | I4: T8 | J4: T9 | K4: T10
A5: Fase del plan | B5: Fase 0 | C5: Fase 0 | D5: Fase 1 | E5: Fase 1 | F5: Fase 1-2 | G5: Fase 2 | H5: Fase 2-3 | I5: Fase 3 | J5: Fase 3 | K5: Fase 3
A7: ENTRADAS
A8: Licencias vendidas (ud.) | B8: 0 | C8: 0 | D8: 60 | E8: 120 | F8: 180 | G8: 300 | H8: 420 | I8: 600 | J8: 800 | K8: 900
A9: Kits vendidos (ud.) | B9: 0 | C9: 0 | D9: 0 | E9: 0 | F9: 8 | G9: 18 | H9: 30 | I9: 45 | J9: 60 | K9: 80
A10: Mesas vendidas (ud.) | B10: 0 | C10: 0 | D10: 0 | E10: 0 | F10: 0 | G10: 0 | H10: 4 | I10: 8 | J10: 150 | K10: 20
A11: Ingreso por licencias | B11: =B8*'Economia unitaria'!$B$19 -> 0 | C11: =C8*'Economia unitaria'!$B$19 -> 0 | D11: =D8*'Economia unitaria'!$B$19 -> 2940 | E11: =E8*'Economia unitaria'!$B$19 -> 5880 | F11: =F8*'Economia unitaria'!$B$19 -> 8820 | G11: =G8*'Economia unitaria'!$B$19 -> 14700 | H11: =H8*'Economia unitaria'!$B$19 -> 20580 | I11: =I8*'Economia unitaria'!$B$19 -> 29400 | ... K11: =K8*'Economia unitaria'!$B$19 -> 44100
A12: Ingreso por kits | B12: =B9*'Economia unitaria'!$D$7 -> 0 | C12: =C9*'Economia unitaria'!$D$7 -> 0 | D12: =D9*'Economia unitaria'!$D$7 -> 0 | E12: =E9*'Economia unitaria'!$D$7 -> 0 | F12: =F9*'Economia unitaria'!$D$7 -> 5282.6446 | G12: =G9*'Economia unitaria'!$D$7 -> 11885.95 | H12: =H9*'Economia unitaria'!$D$7 -> 19809.917 | I12: =I9*'Economia unitaria'!$D$7 -> 29714.876 | ... K12: =K9*'Economia unitaria'!$D$7 -> 52826.446
A13: Ingreso por mesas (neto de IVA) | B13: =B10*'Economia unitaria'!$B$7 -> 0 | C13: =C10*'Economia unitaria'!$B$7 -> 0 | D13: =D10*'Economia unitaria'!$B$7 -> 0 | E13: =E10*'Economia unitaria'!$B$7 -> 0 | F13: =F10*'Economia unitaria'!$B$7 -> 0 | G13: =G10*'Economia unitaria'!$B$7 -> 0 | H13: =H10*'Economia unitaria'!$B$7 -> 9583.4711 | I13: =I10*'Economia unitaria'!$B$7 -> 19166.942 | ... K13: =K10*'Economia unitaria'!$B$7 -> 47917.355
A14: TOTAL ENTRADAS | B14: =SUM(B11:B13) -> 0 | C14: =SUM(C11:C13) -> 0 | D14: =SUM(D11:D13) -> 2940 | E14: =SUM(E11:E13) -> 5880 | F14: =SUM(F11:F13) -> 14102.645 | G14: =SUM(G11:G13) -> 26585.95 | H14: =SUM(H11:H13) -> 49973.388 | I14: =SUM(I11:I13) -> 78281.818 | ... K14: =SUM(K11:K13) -> 144843.8
A16: SALIDAS
A17: Gastos fijos | B17: =-Supuestos!$B$44*3 -> -1350 | C17: =-Supuestos!$B$44*3 -> -1350 | D17: =-Supuestos!$B$44*3 -> -1350 | E17: =-Supuestos!$B$44*3 -> -1350 | F17: =-Supuestos!$B$44*3 -> -1350 | G17: =-Supuestos!$B$44*3 -> -1350 | H17: =-Supuestos!$B$44*3 -> -1350 | I17: =-Supuestos!$B$44*3 -> -1350 | ... K17: =-Supuestos!$B$44*3 -> -1350
A18: Marketing y publicidad | B18: -100 | C18: -300 | D18: -600 | E18: -900 | F18: -1500 | G18: -2500 | H18: -4000 | I18: -9000 | J18: -6000 | K18: -2000
A19: Coste de kits vendidos | B19: =-B9*'BOM kit'!$C$15 -> 0 | C19: =-C9*'BOM kit'!$C$15 -> 0 | D19: =-D9*'BOM kit'!$C$15 -> 0 | E19: =-E9*'BOM kit'!$C$15 -> 0 | F19: =-F9*'BOM kit'!$C$15 -> -2952 | G19: =-G9*'BOM kit'!$C$15 -> -6642 | H19: =-H9*'BOM kit'!$C$15 -> -11070 | I19: =-I9*'BOM kit'!$C$15 -> -16605 | ... K19: =-K9*'BOM kit'!$C$15 -> -29520
A20: Coste de mesas vendidas | B20: =-B10*'BOM mesa'!$C$24 -> 0 | C20: =-C10*'BOM mesa'!$C$24 -> 0 | D20: =-D10*'BOM mesa'!$C$24 -> 0 | E20: =-E10*'BOM mesa'!$C$24 -> 0 | F20: =-F10*'BOM mesa'!$C$24 -> 0 | G20: =-G10*'BOM mesa'!$C$24 -> 0 | H20: =-H10*'BOM mesa'!$C$24 -> -4228 | I20: =-I10*'BOM mesa'!$C$24 -> -8456 | ... K20: =-K10*'BOM mesa'!$C$24 -> -21140
A21: Prototipos | B21: 0 | C21: -1500 | D21: -1500 | E21: -1500 | F21: -1500 | G21: 0 | H21: 0 | I21: 0 | J21: 0 | K21: 0
A22: Certificacion y expediente tecnico | B22: 0 | C22: 0 | D22: 0 | E22: 0 | F22: 0 | G22: -2000 | H22: -2700 | I22: 0 | J22: 0 | K22: 0
A23: Utillaje y plantillas | B23: 0 | C23: 0 | D23: 0 | E23: 0 | F23: 0 | G23: 0 | H23: -3000 | I23: -6000 | J23: 0 | K23: 0
A24: Inventario inicial de kits | B24: 0 | C24: 0 | D24: 0 | E24: -4000 | F24: -4000 | G24: -4000 | H24: 0 | I24: 0 | J24: 0 | K24: 0
A25: TOTAL SALIDAS | B25: =SUM(B17:B24) -> -1450 | C25: =SUM(C17:C24) -> -3150 | D25: =SUM(D17:D24) -> -3450 | E25: =SUM(E17:E24) -> -7750 | F25: =SUM(F17:F24) -> -11302 | G25: =SUM(G17:G24) -> -16492 | H25: =SUM(H17:H24) -> -26348 | I25: =SUM(I17:I24) -> -41411 | ... K25: =SUM(K17:K24) -> -54010
A27: FLUJO DEL TRIMESTRE | B27: =B14+B25 -> -1450 | C27: =C14+C25 -> -3150 | D27: =D14+D25 -> -510 | E27: =E14+E25 -> -1870 | F27: =F14+F25 -> 2800.6446 | G27: =G14+G25 -> 10093.95 | H27: =H14+H25 -> 23625.388 | I27: =I14+I25 -> 36870.818 | ... K27: =K14+K25 -> 90833.802
A28: Caja al inicio | B28: =Supuestos!$B$7 -> 5000 | C28: =B29 -> 3550 | D28: =C29 -> 400 | E28: =D29 -> -110 | F28: =E29 -> -1980 | G28: =F29 -> 820.64463 | H28: =G29 -> 10914.595 | I28: =H29 -> 34539.983 | J28: =I29 -> 71410.802 | K28: =J29 -> 321570.8
A29: CAJA AL CIERRE | B29: =B28+B27 -> 3550 | C29: =C28+C27 -> 400 | D29: =D28+D27 -> -110 | E29: =E28+E27 -> -1980 | F29: =F28+F27 -> 820.64463 | G29: =G28+G27 -> 10914.595 | H29: =H28+H27 -> 34539.983 | I29: =I28+I27 -> 71410.802 | ... K29: =K28+K27 -> 412404.6
A30: Trimestre en numeros rojos | B30: =IF(B29<0,"SI","") | C30: =IF(C29<0,"SI","") | D30: =IF(D29<0,"SI","") -> SI | E30: =IF(E29<0,"SI","") -> SI | F30: =IF(F29<0,"SI","") | G30: =IF(G29<0,"SI","") | H30: =IF(H29<0,"SI","") | I30: =IF(I29<0,"SI","") | ... K30: =IF(K29<0,"SI","")
A32: Las filas azules sobre amarillo son escenario, no prediccion: cambialas para ver como responde la caja.
A33: Si alguna casilla de la fila 30 dice SI, ese trimestre necesitas financiacion antes de llegar a el. Ver la escalera de financiacion en MRPG-BIZ-01 §08.
